<?xml version="1.0" ?>
<robot name="virat" command="$(find xacro)/xacro -- inorder '$(find Gazebo_Virat)urdf/virat.urdf">
    <link name="castors1">
        <inertial>
            <mass value="0.1"/>
            <origin rpy="0 0 0" xyz="0.427 0 0.0"/>
            <inertia ixx="0.3" ixy="0" ixz="0" iyy="0.1" iyz="0" izz="0.1"/>
        </inertial>
        <collision name="collision">
            <origin rpy="0 0 0" xyz="0.427 0 0.0"/>
            <geometry>
                <mesh filename="package://Gazebo_Virat/models/castors1/meshes/castors1.dae"/>
            </geometry>
        </collision>
        <visual name="visual">
            <origin rpy="0 0 0" xyz="0.427 0 0.0"/>
            <geometry>
                <mesh filename="package://Gazebo_Virat/models/castors1/meshes/castors1.dae"/>
            </geometry>
        </visual>
    </link>

    <link name="bot2">
        <inertial>
            <mass value="5"/>
            <!-- <origin rpy="0 0 0" xyz="0 0 0"/> -->
            <inertia ixx="0" ixy="0" ixz="0" iyy="0.0" iyz="0" izz="0"/>
        </inertial>
        <collision name="collision">
            <geometry>
                <mesh filename="package://Gazebo_Virat/models/bot2/meshes/bot2.dae"/>
            </geometry>
        </collision>
        <visual name="visual">
            <!-- <origin rpy="0 0 0" xyz="0 0 0"/> -->
            <geometry>
                <mesh filename="package://Gazebo_Virat/models/bot2/meshes/bot2.dae"/>
            </geometry>
        </visual>
    </link>

    <joint name="castor_bot" type="fixed">
        <parent link="bot2"/>
        <child link="castors1"/>
    </joint>
    
    <link name="left_wheel">
        <inertial>
            <mass value="0.5"/>
            <origin rpy="0 0 0" xyz="0 0.332 0.0"/>
            <inertia ixx="0.3" ixy="0" ixz="0" iyy="0.1" iyz="0" izz="0.1"/>
        </inertial>
        <collision name="collision">
            <origin rpy="0 0 0" xyz="0 0.332 0.0"/>
            <geometry>
                <mesh filename="package://Gazebo_Virat/models/tyre1/meshes/tyre1.dae"/>
            </geometry>
        </collision>
        <visual name="visual">
            <origin rpy="0 0 0" xyz="0 0.332 0.0"/>
            <geometry>
                <mesh filename="package://Gazebo_Virat/models/tyre1/meshes/tyre1.dae"/>
            </geometry>
        </visual>
    </link>

    <link name="right_wheel">
        <inertial>
            <mass value="0.5"/>
            <origin rpy="0 0 0" xyz="0 -0.332 0.0"/>
            <inertia ixx="0.3" ixy="0" ixz="0" iyy="0.1" iyz="0" izz="0.1"/>
        </inertial>
        <collision name="collision">
            <origin rpy="0 0 0" xyz="0 -0.332 0.0"/>
            <geometry>
                <mesh filename="package://Gazebo_Virat/models/tyre1/meshes/tyre1.dae"/>
            </geometry>
        </collision>
        <visual name="visual">
            <origin rpy="0 0 0" xyz="0 -0.332 0.0"/>
            <geometry>
                <mesh filename="package://Gazebo_Virat/models/tyre1/meshes/tyre1.dae"/>
            </geometry>
        </visual>
    </link>

    <joint name="lwheel_bot2" type="continuous">
        <parent link="bot2"/>
        <child link="left_wheel"/>
        <axis xyz="0 1 0"/>
        <origin xyz="0 0 0"/>
    </joint>

    <joint name="rwheel_bot2" type="continuous">
        <parent link="bot2"/>
        <child link="right_wheel"/>
        <axis xyz="0 1 0"/>
        <origin xyz="0 0 0"/>
    </joint>
</robot>
 